Workbook
Name SimNao: Metas!$Q$2:$Q$3

Sheet Metas
A1: ID_Area | B1: Área | C1: Tema | D1: ID_Meta | E1: Descrição da Meta | F1: Status da Meta | G1: % Avanço | H1: Data Inicio | I1: Data Fim | J1: Duração | K1: ID_Responsavel | L1: Responsável | M1: Empresa | N1: Observação de Acompanhamento | O1: Concluí em 2025?
A2: =IFERROR(INDEX(Tabela2[ID_Area], MATCH(B2,Tabela2[Area], 0)), "Não encontrado") -> 1004 | B2: Licenciamento & Regulatório | C2: Licenciamento | D2: =ROW(D2) +98 -> 100 | E2: Atender a Lei SNUC/SEUC e Lei de FAUNA dentro dos prazos estabelecidos pelos órgãos reguladores | F2: =IF(G2=1,"Concluído", IF(TODAY()>I2,"Atrasado", IF(AND(G2=0,TODAY()<I2),"Não iniciado", "Em Andamento"))) -> Atrasado | G2: {=SUMPRODUCT( (Atividades!$E$2:$E$598=Metas!E2) * (Atividades!$O$2:$O$598=Metas!L2), Atividades!$I$2:$I$598, Atividades!$J$2:$J$598 ) / SUMPRODUCT( (Atividades!$E$2:$E$598=Metas!E2) * (Atividades!$O$2:$O$598=Metas!L2), Atividades!$J$2:$J$598 )} -> 0.96842828 | H2: 45658 | I2: 46008 | J2: =I2-H2 -> 350 | K2: =IFERROR(INDEX(Tabela3[ID_Responsavel], MATCH(L2,Tabela3[[Responsáveis ]], 0)), "Não encontrado") -> 25 | L2: Thiago Viana | M2: SVPM | N2: Pendência da SEMAD. Dentro das ações de responsabilidade GMA, tudo foi cumprido conforme proposto para 2025. Continuidade 2026 conforme aditivo TCCA e Aditivos contratuai | O2: Não | Q2: Sim
A3: =IFERROR(INDEX(Tabela2[ID_Area], MATCH(B3,Tabela2[Area], 0)), "Não encontrado") -> 1004 | B3: Licenciamento & Regulatório | C3: Licenciamento | D3: =ROW(D3) +98 -> 101 | E3: Concluir o processo de solicitação de aditivo ao Termo de Compromisso Ambiental do SNUC/SEUC do processo de complementação das estruturas licenciadas_Thiago | F3: =IF(G3=1,"Concluído", IF(TODAY()>I3,"Atrasado", IF(AND(G3=0,TODAY()<I3),"Não iniciado", "Em Andamento"))) -> Concluído | G3: {=SUMPRODUCT( (Atividades!$E$2:$E$598=Metas!E3) * (Atividades!$O$2:$O$598=Metas!L3), Atividades!$I$2:$I$598, Atividades!$J$2:$J$598 ) / SUMPRODUCT( (Atividades!$E$2:$E$598=Metas!E3) * (Atividades!$O$2:$O$598=Metas!L3), Atividades!$J$2:$J$598 )} -> 1 | H3: 45658 | I3: 45933 | J3: =I3-H3 -> 275 | K3: =IFERROR(INDEX(Tabela3[ID_Responsavel], MATCH(L3,Tabela3[[Responsáveis ]], 0)), "Não encontrado") -> 25 | L3: Thiago Viana | M3: SVPM | Q3: Não
A4: =IFERROR(INDEX(Tabela2[ID_Area], MATCH(B4,Tabela2[Area], 0)), "Não encontrado") -> 1004 | B4: Licenciamento & Regulatório | C4: SGA | D4: =ROW(D4) +98 -> 102 | E4: Desenvolver e implementar estratégia para implantação da SGA ISO 14001 | F4: =IF(G4=1,"Concluído", IF(TODAY()>I4,"Atrasado", IF(AND(G4=0,TODAY()<I4),"Não iniciado", "Em Andamento"))) -> Atrasado | G4: {=SUMPRODUCT( (Atividades!$E$2:$E$598=Metas!E4) * (Atividades!$O$2:$O$598=Metas!L4), Atividades!$I$2:$I$598, Atividades!$J$2:$J$598 ) / SUMPRODUCT( (Atividades!$E$2:$E$598=Metas!E4) * (Atividades!$O$2:$O$598=Metas!L4), Atividades!$J$2:$J$598 )} -> 0.78294885 | H4: 45717 | I4: 45960 | J4: =I4-H4 -> 243 | K4: =IFERROR(INDEX(Tabela3[ID_Responsavel], MATCH(L4,Tabela3[[Responsáveis ]], 0)), "Não encontrado") -> 25 | L4: Thiago Viana | M4: SVPM | N4: Continuidade em 2026. Itens do Manual SGA e Aspectos e Impactos com base na nova estrutura e planejamento integrado da Gerência. Alinhado com Gestor a prorrogação da meta, devido foco em outros temas prioritários (RDA e Licenciamentos) | O4: Não
A5: =IFERROR(INDEX(Tabela2[ID_Area], MATCH(B5,Tabela2[Area], 0)), "Não encontrado") -> 1004 | B5: Licenciamento & Regulatório | C5: Licenciamento | D5: =ROW(D5) +98 -> 103 | E5: Cumprir plano de licenciamento (ASV, Heap Leaching, renovação, integração)_Thiago | F5: =IF(G5=1,"Concluído", IF(TODAY()>I5,"Atrasado", IF(AND(G5=0,TODAY()<I5),"Não iniciado", "Em Andamento"))) -> Concluído | G5: {=SUMPRODUCT( (Atividades!$E$2:$E$598=Metas!E5) * (Atividades!$O$2:$O$598=Metas!L5), Atividades!$I$2:$I$598, Atividades!$J$2:$J$598 ) / SUMPRODUCT( (Atividades!$E$2:$E$598=Metas!E5) * (Atividades!$O$2:$O$598=Metas!L5), Atividades!$J$2:$J$598 )} -> 1 | H5: 45659 | I5: 46004 | J5: =I5-H5 -> 345 | K5: =IFERROR(INDEX(Tabela3[ID_Responsavel], MATCH(L5,Tabela3[[Responsáveis ]], 0)), "Não encontrado") -> 25 | L5: Thiago Viana | M5: SVPM
A6: =IFERROR(INDEX(Tabela2[ID_Area], MATCH(B6,Tabela2[Area], 0)), "Não encontrado") -> 1004 | B6: Licenciamento & Regulatório | C6: Licenciamento | D6: =ROW(D6) +98 -> 104 | E6: Desenvolver Masterplan de Licenciamento Ambiental da SVPM_Thiago | F6: =IF(G6=1,"Concluído", IF(TODAY()>I6,"Atrasado", IF(AND(G6=0,TODAY()<I6),"Não iniciado", "Em Andamento"))) -> Concluído | G6: {=SUMPRODUCT( (Atividades!$E$2:$E$598=Metas!E6) * (Atividades!$O$2:$O$598=Metas!L6), Atividades!$I$2:$I$598, Atividades!$J$2:$J$598 ) / SUMPRODUCT( (Atividades!$E$2:$E$598=Metas!E6) * (Atividades!$O$2:$O$598=Metas!L6), Atividades!$J$2:$J$598 )} -> 1 | H6: 45901 | I6: 46006 | J6: =I6-H6 -> 105 | K6: =IFERROR(INDEX(Tabela3[ID_Responsavel], MATCH(L6,Tabela3[[Responsáveis ]], 0)), "Não encontrado") -> 25 | L6: Thiago Viana | M6: SVPM
A7: =IFERROR(INDEX(Tabela2[ID_Area], MATCH(B7,Tabela2[Area], 0)), "Não encontrado") -> 1004 | B7: Licenciamento & Regulatório | C7: SGA | D7: =ROW(D7) +98 -> 105 | E7: Implementar sistema de requisitos legais ambientais | F7: =IF(G7=1,"Concluído", IF(TODAY()>I7,"Atrasado", IF(AND(G7=0,TODAY()<I7),"Não iniciado", "Em Andamento"))) -> Concluído | G7: {=SUMPRODUCT( (Atividades!$E$2:$E$598=Metas!E7) * (Atividades!$O$2:$O$598=Metas!L7), Atividades!$I$2:$I$598, Atividades!$J$2:$J$598 ) / SUMPRODUCT( (Atividades!$E$2:$E$598=Metas!E7) * (Atividades!$O$2:$O$598=Metas!L7), Atividades!$J$2:$J$598 )} -> 1 | H7: 45658 | I7: 45901 | J7: =I7-H7 -> 243 | K7: =IFERROR(INDEX(Tabela3[ID_Responsavel], MATCH(L7,Tabela3[[Responsáveis ]], 0)), "Não encontrado") -> 3 | L7: Anna Laura | M7: SESI
A8: =IFERROR(INDEX(Tabela2[ID_Area], MATCH(B8,Tabela2[Area], 0)), "Não encontrado") -> 1004 | B8: Licenciamento & Regulatório | C8: SGA | D8: =ROW(D8) +98 -> 106 | E8: Realizar gap analysis da ISO14001 nas áreas | F8: =IF(G8=1,"Concluído", IF(TODAY()>I8,"Atrasado", IF(AND(G8=0,TODAY()<I8),"Não iniciado", "Em Andamento"))) -> Concluído | G8: {=SUMPRODUCT( (Atividades!$E$2:$E$598=Metas!E8) * (Atividades!$O$2:$O$598=Metas!L8), Atividades!$I$2:$I$598, Atividades!$J$2:$J$598 ) / SUMPRODUCT( (Atividades!$E$2:$E$598=Metas!E8) * (Atividades!$O$2:$O$598=Metas!L8), Atividades!$J$2:$J$598 )} -> 1 | H8: 45677 | I8: 46021 | J8: =I8-H8 -> 344 | K8: =IFERROR(INDEX(Tabela3[ID_Responsavel], MATCH(L8,Tabela3[[Responsáveis ]], 0)), "Não encontrado") -> 3 | L8: Anna Laura | M8: SESI
A9: =IFERROR(INDEX(Tabela2[ID_Area], MATCH(B9,Tabela2[Area], 0)), "Não encontrado") -> 1004 | B9: Licenciamento & Regulatório | C9: Regulatório | D9: =ROW(D9) +98 -> 107 | E9: Estruturação da BASE DE DADOS e plano de atendimento aos itens regulatórios Fundiários, Minerários e Passivos Ambientais das propriedades_AnnaLaura | F9: =IF(G9=1,"Concluído", IF(TODAY()>I9,"Atrasado", IF(AND(G9=0,TODAY()<I9),"Não iniciado", "Em Andamento"))) -> Concluído | G9: {=SUMPRODUCT( (Atividades!$E$2:$E$598=Metas!E9) * (Atividades!$O$2:$O$598=Metas!L9), Atividades!$I$2:$I$598, Atividades!$J$2:$J$598 ) / SUMPRODUCT( (Atividades!$E$2:$E$598=Metas!E9) * (Atividades!$O$2:$O$598=Metas!L9), Atividades!$J$2:$J$598 )} -> 1 | H9: 45677 | I9: 46021 | J9: =I9-H9 -> 344 | K9: =IFERROR(INDEX(Tabela3[ID_Responsavel], MATCH(L9,Tabela3[[Responsáveis ]], 0)), "Não encontrado") -> 3 | L9: Anna Laura | M9: SESI | O9: Sim
A10: =IFERROR(INDEX(Tabela2[ID_Area], MATCH(B10,Tabela2[Area], 0)), "Não encontrado") -> 1004 | B10: Licenciamento & Regulatório | C10: Licenciamento | D10: =ROW(D10) +98 -> 108 | E10: Concluir o processo de solicitação de aditivo ao Termo de Compromisso Ambiental do SNUC/SEUC do processo de complementação das estruturas licenciadas_AnnaLaura | F10: =IF(G10=1,"Concluído", IF(TODAY()>I10,"Atrasado", IF(AND(G10=0,TODAY()<I10),"Não iniciado", "Em Andamento"))) -> Concluído | G10: {=SUMPRODUCT( (Atividades!$E$2:$E$598=Metas!E10) * (Atividades!$O$2:$O$598=Metas!L10), Atividades!$I$2:$I$598, Atividades!$J$2:$J$598 ) / SUMPRODUCT( (Atividades!$E$2:$E$598=Metas!E10) * (Atividades!$O$2:$O$598=Metas!L10), Atividades!$J$2:$J$598 )} -> 1 | H10: 45659 | I10: 46004 | J10: =I10-H10 -> 345 | K10: =IFERROR(INDEX(Tabela3[ID_Responsavel], MATCH(L10,Tabela3[[Responsáveis ]], 0)), "Não encontrado") -> 3 | L10: Anna Laura | M10: SESI
A11: =IFERROR(INDEX(Tabela2[ID_Area], MATCH(B11,Tabela2[Area], 0)), "Não encontrado") -> 1004 | B11: Licenciamento & Regulatório | C11: Licenciamento | D11: =ROW(D11) +98 -> 109 | E11: Acompanhar o processo de Renovação da Licença de Instalação pelo sistema SGA junto a SEMAD | F11: =IF(G11=1,"Concluído", IF(TODAY()>I11,"Atrasado", IF(AND(G11=0,TODAY()<I11),"Não iniciado", "Em Andamento"))) -> Concluído | G11: {=SUMPRODUCT( (Atividades!$E$2:$E$598=Metas!E11) * (Atividades!$O$2:$O$598=Metas!L11), Atividades!$I$2:$I$598, Atividades!$J$2:$J$598 ) / SUMPRODUCT( (Atividades!$E$2:$E$598=Metas!E11) * (Atividades!$O$2:$O$598=Metas!L11), Atividades!$J$2:$J$598 )} -> 1 | H11: 45659 | I11: 46021 | J11: =I11-H11 -> 362 | K11: =IFERROR(INDEX(Tabela3[ID_Responsavel], MATCH(L11,Tabela3[[Responsáveis ]], 0)), "Não encontrado") -> 3 | L11: Anna Laura | M11: SESI
A12: =IFERROR(INDEX(Tabela2[ID_Area], MATCH(B12,Tabela2[Area], 0)), "Não encontrado") -> 1004 | B12: Licenciamento & Regulatório | C12: Licenciamento | D12: =ROW(D12) +98 -> 110 | E12: Cumprir plano de licenciamento (ASV, Heap Leaching, renovação, integração)_Nadrielle | F12: =IF(G12=1,"Concluído", IF(TODAY()>I12,"Atrasado", IF(AND(G12=0,TODAY()<I12),"Não iniciado", "Em Andamento"))) -> Concluído | G12: {=SUMPRODUCT( (Atividades!$E$2:$E$598=Metas!E12) * (Atividades!$O$2:$O$598=Metas!L12), Atividades!$I$2:$I$598, Atividades!$J$2:$J$598 ) / SUMPRODUCT( (Atividades!$E$2:$E$598=Metas!E12) * (Atividades!$O$2:$O$598=Metas!L12), Atividades!$J$2:$J$598 )} -> 1 | H12: 45658 | I12: 46022 | J12: =I12-H12 -> 364 | K12: =IFERROR(INDEX(Tabela3[ID_Responsavel], MATCH(L12,Tabela3[[Responsáveis ]], 0)), "Não encontrado") -> 20 | L12: Nadrielle | M12: SVPM | O12: Sim
A13: =IFERROR(INDEX(Tabela2[ID_Area], MATCH(B13,Tabela2[Area], 0)), "Não encontrado") -> 1004 | B13: Licenciamento & Regulatório | C13: Gestão de Custo | D13: =ROW(D13) +98 -> 111 | E13: Propor revisão de contratos vigentes buscando reduzir custos | F13: =IF(G13=1,"Concluído", IF(TODAY()>I13,"Atrasado", IF(AND(G13=0,TODAY()<I13),"Não iniciado", "Em Andamento"))) -> Atrasado | G13: {=SUMPRODUCT( (Atividades!$E$2:$E$598=Metas!E13) * (Atividades!$O$2:$O$598=Metas!L13), Atividades!$I$2:$I$598, Atividades!$J$2:$J$598 ) / SUMPRODUCT( (Atividades!$E$2:$E$598=Metas!E13) * (Atividades!$O$2:$O$598=Metas!L13), Atividades!$J$2:$J$598 )} -> 0.3105042 | H13: 45663 | I13: 45991 | J13: =I13-H13 -> 328 | K13: =IFERROR(INDEX(Tabela3[ID_Responsavel], MATCH(L13,Tabela3[[Responsáveis ]], 0)), "Não encontrado") -> 20 | L13: Nadrielle | M13: SVPM | O13: Não
A14: =IFERROR(INDEX(Tabela2[ID_Area], MATCH(B14,Tabela2[Area], 0)), "Não encontrado") -> 1004 | B14: Licenciamento & Regulatório | C14: Publicações científicas | D14: =ROW(D14) +98 -> 112 | E14: Desenvolver Masterplan de Licenciamento Ambiental da SVPM_Nadrielle | F14: =IF(G14=1,"Concluído", IF(TODAY()>I14,"Atrasado", IF(AND(G14=0,TODAY()<I14),"Não iniciado", "Em Andamento"))) -> Concluído | G14: {=SUMPRODUCT( (Atividades!$E$2:$E$598=Metas!E14) * (Atividades!$O$2:$O$598=Metas!L14), Atividades!$I$2:$I$598, Atividades!$J$2:$J$598 ) / SUMPRODUCT( (Atividades!$E$2:$E$598=Metas!E14) * (Atividades!$O$2:$O$598=Metas!L14), Atividades!$J$2:$J$598 )} -> 1 | H14: 45663 | I14: 45960 | J14: =I14-H14 -> 297 | K14: =IFERROR(INDEX(Tabela3[ID_Responsavel], MATCH(L14,Tabela3[[Responsáveis ]], 0)), "Não encontrado") -> 20 | L14: Nadrielle | M14: SVPM | O14: Sim
A15: =IFERROR(INDEX(Tabela2[ID_Area], MATCH(B15,Tabela2[Area], 0)), "Não encontrado") -> 1004 | B15: Licenciamento & Regulatório | C15: SGA | D15: =ROW(D15) +98 -> 113 | E15: Estruturar BASE de DADOS geoespaciais (GMA)_Nadrielle | F15: =IF(G15=1,"Concluído", IF(TODAY()>I15,"Atrasado", IF(AND(G15=0,TODAY()<I15),"Não iniciado", "Em Andamento"))) -> Concluído | G15: {=SUMPRODUCT( (Atividades!$E$2:$E$598=Metas!E15) * (Atividades!$O$2:$O$598=Metas!L15), Atividades!$I$2:$I$598, Atividades!$J$2:$J$598 ) / SUMPRODUCT( (Atividades!$E$2:$E$598=Metas!E15) * (Atividades!$O$2:$O$598=Metas!L15), Atividades!$J$2:$J$598 )} -> 1 | H15: 45717 | I15: 45960 | J15: =I15-H15 -> 243 | K15: =IFERROR(INDEX(Tabela3[ID_Responsavel], MATCH(L15,Tabela3[[Responsáveis ]], 0)), "Não encontrado") -> 20 | L15: Nadrielle | M15: SVPM | O15: Sim
A16: =IFERROR(INDEX(Tabela2[ID_Area], MATCH(B16,Tabela2[Area], 0)), "Não encontrado") -> 1004 | B16: Licenciamento & Regulatório | C16: Licenciamento | D16: =ROW(D16) +98 -> 114 | E16: Atender a Lei SNUC/SEUC e Lei de FAUNA dentro dos prazos estabelecidos pelos órgãos reguladores_Nadrielle | F16: =IF(G16=1,"Concluído", IF(TODAY()>I16,"Atrasado", IF(AND(G16=0,TODAY()<I16),"Não iniciado", "Em Andamento"))) -> Atrasado | G16: {=SUMPRODUCT( (Atividades!$E$2:$E$598=Metas!E16) * (Atividades!$O$2:$O$598=Metas!L16), Atividades!$I$2:$I$598, Atividades!$J$2:$J$598 ) / SUMPRODUCT( (Atividades!$E$2:$E$598=Metas!E16) * (Atividades!$O$2:$O$598=Metas!L16), Atividades!$J$2:$J$598 )} -> 0.96842828 | H16: 45658 | I16: 46008 | J16: =I16-H16 -> 350 | K16: =IFERROR(INDEX(Tabela3[ID_Responsavel], MATCH(L16,Tabela3[[Responsáveis ]], 0)), "Não encontrado") -> 20 | L16: Nadrielle | M16: SVPM | O16: Sim
A17: =IFERROR(INDEX(Tabela2[ID_Area], MATCH(B17,Tabela2[Area], 0)), "Não encontrado") -> 1004 | B17: Licenciamento & Regulatório | C17: Regulatório | D17: =ROW(D17) +98 -> 115 | E17: Estruturação da BASE DE DADOS e plano de atendimento aos itens regulatórios Fundiários, Minerários e Passivos Ambientais das propriedades_Nadrielle | F17: =IF(G17=1,"Concluído", IF(TODAY()>I17,"Atrasado", IF(AND(G17=0,TODAY()<I17),"Não iniciado", "Em Andamento"))) -> Concluído | G17: {=SUMPRODUCT( (Atividades!$E$2:$E$598=Metas!E17) * (Atividades!$O$2:$O$598=Metas!L17), Atividades!$I$2:$I$598, Atividades!$J$2:$J$598 ) / SUMPRODUCT( (Atividades!$E$2:$E$598=Metas!E17) * (Atividades!$O$2:$O$598=Metas!L17), Atividades!$J$2:$J$598 )} -> 1 | H17: 45748 | I17: 45991 | J17: =I17-H17 -> 243 | K17: =IFERROR(INDEX(Tabela3[ID_Responsavel], MATCH(L17,Tabela3[[Responsáveis ]], 0)), "Não encontrado") -> 20 | L17: Nadrielle | M17: SVPM | O17: Sim
A18: =IFERROR(INDEX(Tabela2[ID_Area], MATCH(B18,Tabela2[Area], 0)), "Não encontrado") -> 1004 | B18: Licenciamento & Regulatório | C18: SGA | D18: =ROW(D18) +98 -> 116 | E18: Elaborar Procedimento de Aspectos e Impactos Ambientais e Executar Piloto em 01 Área | F18: =IF(G18=1,"Concluído", IF(TODAY()>I18,"Atrasado", IF(AND(G18=0,TODAY()<I18),"Não iniciado", "Em Andamento"))) -> Atrasado | G18: {=SUMPRODUCT( (Atividades!$E$2:$E$598=Metas!E18) * (Atividades!$O$2:$O$598=Metas!L18), Atividades!$I$2:$I$598, Atividades!$J$2:$J$598 ) / SUMPRODUCT( (Atividades!$E$2:$E$598=Metas!E18) * (Atividades!$O$2:$O$598=Metas!L18), Atividades!$J$2:$J$598 )} -> 0.1744186 | H18: 45931 | I18: 46013 | J18: =I18-H18 -> 82 | K18: =IFERROR(INDEX(Tabela3[ID_Responsavel], MATCH(L18,Tabela3[[Responsáveis ]], 0)), "Não encontrado") -> 24 | L18: Thayna | M18: BIOTA | N18: Continuidade em 2026 | O18: Não
A19: =IFERROR(INDEX(Tabela2[ID_Area], MATCH(B19,Tabela2[Area], 0)), "Não encontrado") -> 1004 | B19: Licenciamento & Regulatório | C19: SGA | D19: =ROW(D19) +98 -> 117 | E19: Executar e consolidar sistemática de atualização e consolidação das informações para elaboração RDA 2026/2025_Thayna | F19: =IF(G19=1,"Concluído", IF(TODAY()>I19,"Atrasado", IF(AND(G19=0,TODAY()<I19),"Não iniciado", "Em Andamento"))) -> Concluído | G19: {=SUMPRODUCT( (Atividades!$E$2:$E$598=Metas!E19) * (Atividades!$O$2:$O$598=Metas!L19), Atividades!$I$2:$I$598, Atividades!$J$2:$J$598 ) / SUMPRODUCT( (Atividades!$E$2:$E$598=Metas!E19) * (Atividades!$O$2:$O$598=Metas!L19), Atividades!$J$2:$J$598 )} -> 1 | H19: 45748 | I19: 46013 | J19: =I19-H19 -> 265 | K19: =IFERROR(INDEX(Tabela3[ID_Responsavel], MATCH(L19,Tabela3[[Responsáveis ]], 0)), "Não encontrado") -> 24 | L19: Thayna | M19: BIOTA | O19: Sim
A20: =IFERROR(INDEX(Tabela2[ID_Area], MATCH(B20,Tabela2[Area], 0)), "Não encontrado") -> 1004 | B20: Licenciamento & Regulatório | C20: Regulatório | D20: =ROW(D20) +98 -> 118 | E20: Estruturação da BASE DE DADOS e plano de atendimento aos itens regulatórios Fundiários, Minerários e Passivos Ambientais das propriedades_Thayna | F20: =IF(G20=1,"Concluído", IF(TODAY()>I20,"Atrasado", IF(AND(G20=0,TODAY()<I20),"Não iniciado", "Em Andamento"))) -> Concluído | G20: {=SUMPRODUCT( (Atividades!$E$2:$E$598=Metas!E20) * (Atividades!$O$2:$O$598=Metas!L20), Atividades!$I$2:$I$598, Atividades!$J$2:$J$598 ) / SUMPRODUCT( (Atividades!$E$2:$E$598=Metas!E20) * (Atividades!$O$2:$O$598=Metas!L20), Atividades!$J$2:$J$598 )} -> 1 | H20: 45748 | I20: 45991 | J20: =I20-H20 -> 243 | K20: =IFERROR(INDEX(Tabela3[ID_Responsavel], MATCH(L20,Tabela3[[Responsáveis ]], 0)), "Não encontrado") -> 24 | L20: Thayna | M20: BIOTA | O20: Sim
A21: =IFERROR(INDEX(Tabela2[ID_Area], MATCH(B21,Tabela2[Area], 0)), "Não encontrado") -> 1004 | B21: Licenciamento & Regulatório | C21: Licenciamento | D21: =ROW(D21) +98 -> 119 | E21: Diligenciar no acompanhamento das solicitações de exclusões de condicionantes | F21: =IF(G21=1,"Concluído", IF(TODAY()>I21,"Atrasado", IF(AND(G21=0,TODAY()<I21),"Não iniciado", "Em Andamento"))) -> Concluído | G21: {=SUMPRODUCT( (Atividades!$E$2:$E$598=Metas!E21) * (Atividades!$O$2:$O$598=Metas!L21), Atividades!$I$2:$I$598, Atividades!$J$2:$J$598 ) / SUMPRODUCT( (Atividades!$E$2:$E$598=Metas!E21) * (Atividades!$O$2:$O$598=Metas!L21), Atividades!$J$2:$J$598 )} -> 1 | H21: 45670 | I21: 45716 | J21: =I21-H21 -> 46 | K21: =IFERROR(INDEX(Tabela3[ID_Responsavel], MATCH(L21,Tabela3[[Responsáveis ]], 0)), "Não encontrado") -> 24 | L21: Thayna | M21: BIOTA
A22: =IFERROR(INDEX(Tabela2[ID_Area], MATCH(B22,Tabela2[Area], 0)), "Não encontrado") -> 1004 | B22: Licenciamento & Regulatório | C22: SGA | D22: =ROW(D22) +98 -> 120 | E22: Desenvolver Manual do SGA | F22: =IF(G22=1,"Concluído", IF(TODAY()>I22,"Atrasado", IF(AND(G22=0,TODAY()<I22),"Não iniciado", "Em Andamento"))) -> Atrasado | G22: {=SUMPRODUCT( (Atividades!$E$2:$E$598=Metas!E22) * (Atividades!$O$2:$O$598=Metas!L22), Atividades!$I$2:$I$598, Atividades!$J$2:$J$598 ) / SUMPRODUCT( (Atividades!$E$2:$E$598=Metas!E22) * (Atividades!$O$2:$O$598=Metas!L22), Atividades!$J$2:$J$598 )} -> 0.525 | H22: 45748 | I22: 45961 | J22: =I22-H22 -> 213 | K22: =IFERROR(INDEX(Tabela3[ID_Responsavel], MATCH(L22,Tabela3[[Responsáveis ]], 0)), "Não encontrado") -> 24 | L22: Thayna | M22: BIOTA | N22: Continuidade em 2026 | O22: Não
A23: =IFERROR(INDEX(Tabela2[ID_Area], MATCH(B23,Tabela2[Area], 0)), "Não encontrado") -> 1000 | B23: Meio Ambiente - Gerencial | C23: P&D | D23: =ROW(D23) +98 -> 121 | E23: SULFATO DE AMÔNIO - Continuidade dos Estudos de Avaliação de Impactos e Ganhos Potenciais com inclusão do reagente S.A. | F23: =IF(G23=1,"Concluído", IF(TODAY()>I23,"Atrasado", IF(AND(G23=0,TODAY()<I23),"Não iniciado", "Em Andamento"))) -> Concluído | G23: {=SUMPRODUCT( (Atividades!$E$2:$E$598=Metas!E23) * (Atividades!$O$2:$O$598=Metas!L23), Atividades!$I$2:$I$598, Atividades!$J$2:$J$598 ) / SUMPRODUCT( (Atividades!$E$2:$E$598=Metas!E23) * (Atividades!$O$2:$O$598=Metas!L23), Atividades!$J$2:$J$598 )} -> 1 | H23: =Atividades!K38 -> 45658 | I23: 46376 | J23: =I23-H23 -> 718 | K23: =IFERROR(INDEX(Tabela3[ID_Responsavel], MATCH(L23,Tabela3[[Responsáveis ]], 0)), "Não encontrado") -> 7 | L23: Edimar Dias | M23: SVPM
A24: =IFERROR(INDEX(Tabela2[ID_Area], MATCH(B24,Tabela2[Area], 0)), "Não encontrado") -> 1000 | B24: Meio Ambiente - Gerencial | C24: P&D | D24: =ROW(D24) +98 -> 122 | E24: TRATABILIDADE EFLUENTES E REJEITOS - Continuidade dos Estudos de Tratabilidade de Efluentes (Salinidade ). | F24: =IF(G24=1,"Concluído", IF(TODAY()>I24,"Atrasado", IF(AND(G24=0,TODAY()<I24),"Não iniciado", "Em Andamento"))) -> Concluído | G24: {=SUMPRODUCT( (Atividades!$E$2:$E$598=Metas!E24) * (Atividades!$O$2:$O$598=Metas!L24), Atividades!$I$2:$I$598, Atividades!$J$2:$J$598 ) / SUMPRODUCT( (Atividades!$E$2:$E$598=Metas!E24) * (Atividades!$O$2:$O$598=Metas!L24), Atividades!$J$2:$J$598 )} -> 1 | H24: =Atividades!K45 -> 45658 | I24: 46091 | J24: =I24-H24 -> 433 | K24: =IFERROR(INDEX(Tabela3[ID_Responsavel], MATCH(L24,Tabela3[[Responsáveis ]], 0)), "Não encontrado") -> 7 | L24: Edimar Dias | M24: SVPM
A25: =IFERROR(INDEX(Tabela2[ID_Area], MATCH(B25,Tabela2[Area], 0)), "Não encontrado") -> 1000 | B25: Meio Ambiente - Gerencial | C25: Regulatório | D25: =ROW(D25) +98 -> 123 | E25: REGULARIZAÇÃO CAR - Atualização das informações e adequação das bases das propriedades inseridas na ADA SVPM conforme prioridade e disponibilidade de recurso. | F25: =IF(G25=1,"Concluído", IF(TODAY()>I25,"Atrasado", IF(AND(G25=0,TODAY()<I25),"Não iniciado", "Em Andamento"))) -> Concluído | G25: {=SUMPRODUCT( (Atividades!$E$2:$E$598=Metas!E25) * (Atividades!$O$2:$O$598=Metas!L25), Atividades!$I$2:$I$598, Atividades!$J$2:$J$598 ) / SUMPRODUCT( (Atividades!$E$2:$E$598=Metas!E25) * (Atividades!$O$2:$O$598=Metas!L25), Atividades!$J$2:$J$598 )} -> 1 | H25: 45847 | I25: 45969 | J25: =I25-H25 -> 122 | K25: =IFERROR(INDEX(Tabela3[ID_Responsavel], MATCH(L25,Tabela3[[Responsáveis ]], 0)), "Não encontrado") -> 7 | L25: Edimar Dias | M25: SESI
A26: =IFERROR(INDEX(Tabela2[ID_Area], MATCH(B26,Tabela2[Area], 0)), "Não encontrado") -> 1000 | B26: Meio Ambiente - Gerencial | C26: SGA | D26: =ROW(D26) +98 -> 124 | E26: Desenvolver e Implementar do Indice de Maturidade e regras socioambientais | F26: =IF(G26=1,"Concluído", IF(TODAY()>I26,"Atrasado", IF(AND(G26=0,TODAY()<I26),"Não iniciado", "Em Andamento"))) -> Concluído | G26: {=SUMPRODUCT( (Atividades!$E$2:$E$598=Metas!E26) * (Atividades!$O$2:$O$598=Metas!L26), Atividades!$I$2:$I$598, Atividades!$J$2:$J$598 ) / SUMPRODUCT( (Atividades!$E$2:$E$598=Metas!E26) * (Atividades!$O$2:$O$598=Metas!L26), Atividades!$J$2:$J$598 )} -> 1 | H26: =Atividades!K16 -> 45674 | I26: 45989 | J26: =I26-H26 -> 315 | K26: =IFERROR(INDEX(Tabela3[ID_Responsavel], MATCH(L26,Tabela3[[Responsáveis ]], 0)), "Não encontrado") -> 7 | L26: Edimar Dias | M26: SESI
A27: =IFERROR(INDEX(Tabela2[ID_Area], MATCH(B27,Tabela2[Area], 0)), "Não encontrado") -> 1000 | B27: Meio Ambiente - Gerencial | C27: Regulatório | D27: =ROW(D27) +98 -> 125 | E27: Atualizar base de APP (Vereda, Nascente e cursos hídricos) das propriedades. | F27: =IF(G27=1,"Concluído", IF(TODAY()>I27,"Atrasado", IF(AND(G27=0,TODAY()<I27),"Não iniciado", "Em Andamento"))) -> Concluído | G27: {=SUMPRODUCT( (Atividades!$E$2:$E$598=Metas!E27) * (Atividades!$O$2:$O$598=Metas!L27), Atividades!$I$2:$I$598, Atividades!$J$2:$J$598 ) / SUMPRODUCT( (Atividades!$E$2:$E$598=Metas!E27) * (Atividades!$O$2:$O$598=Metas!L27), Atividades!$J$2:$J$598 )} -> 1 | H27: =Atividades!K2 -> 45660 | I27: 45989 | J27: =I27-H27 -> 329 | K27: =IFERROR(INDEX(Tabela3[ID_Responsavel], MATCH(L27,Tabela3[[Responsáveis ]], 0)), "Não encontrado") -> 7 | L27: Edimar Dias | M27: SESI
A28: =IFERROR(INDEX(Tabela2[ID_Area], MATCH(B28,Tabela2[Area], 0)), "Não encontrado") -> 1000 | B28: Meio Ambiente - Gerencial | C28: Projeto | D28: =ROW(D28) +98 -> 126 | E28: Rehabilitation Projects Phase II | F28: =IF(G28=1,"Concluído", IF(TODAY()>I28,"Atrasado", IF(AND(G28=0,TODAY()<I28),"Não iniciado", "Em Andamento"))) -> Concluído | G28: {=SUMPRODUCT( (Atividades!$E$2:$E$598=Metas!E28) * (Atividades!$O$2:$O$598=Metas!L28), Atividades!$I$2:$I$598, Atividades!$J$2:$J$598 ) / SUMPRODUCT( (Atividades!$E$2:$E$598=Metas!E28) * (Atividades!$O$2:$O$598=Metas!L28), Atividades!$J$2:$J$598 )} -> 1 | H28: 45663 | I28: 46010 | J28: =I28-H28 -> 347 | K28: =IFERROR(INDEX(Tabela3[ID_Responsavel], MATCH(L28,Tabela3[[Responsáveis ]], 0)), "Não encontrado") -> 7 | L28: Edimar Dias | M28: SESI
A29: =IFERROR(INDEX(Tabela2[ID_Area], MATCH(B29,Tabela2[Area], 0)), "Não encontrado") -> 1000 | B29: Meio Ambiente - Gerencial | C29: Projeto | D29: =ROW(D29) +98 -> 127 | E29: Elaborar Book ambiental dos projetos Flow Sheat | F29: =IF(G29=1,"Concluído", IF(TODAY()>I29,"Atrasado", IF(AND(G29=0,TODAY()<I29),"Não iniciado", "Em Andamento"))) -> Atrasado | G29: {=SUMPRODUCT( (Atividades!$E$2:$E$598=Metas!E29) * (Atividades!$O$2:$O$598=Metas!L29), Atividades!$I$2:$I$598, Atividades!$J$2:$J$598 ) / SUMPRODUCT( (Atividades!$E$2:$E$598=Metas!E29) * (Atividades!$O$2:$O$598=Metas!L29), Atividades!$J$2:$J$598 )} -> 0.0045072273 | H29: 45677 | I29: 46010 | J29: =I29-H29 -> 333 | K29: =IFERROR(INDEX(Tabela3[ID_Responsavel], MATCH(L29,Tabela3[[Responsáveis ]], 0)), "Não encontrado") -> 7 | L29: Edimar Dias | M29: SESI
A30: =IFERROR(INDEX(Tabela2[ID_Area], MATCH(B30,Tabela2[Area], 0)), "Não encontrado") -> 1000 | B30: Meio Ambiente - Gerencial | C30: Projeto | D30: =ROW(D30) +98 -> 128 | E30: Elaborar Book ambiental do Heap Laeth | F30: =IF(G30=1,"Concluído", IF(TODAY()>I30,"Atrasado", IF(AND(G30=0,TODAY()<I30),"Não iniciado", "Em Andamento"))) -> Atrasado | G30: {=SUMPRODUCT( (Atividades!$E$2:$E$598=Metas!E30) * (Atividades!$O$2:$O$598=Metas!L30), Atividades!$I$2:$I$598, Atividades!$J$2:$J$598 ) / SUMPRODUCT( (Atividades!$E$2:$E$598=Metas!E30) * (Atividades!$O$2:$O$598=Metas!L30), Atividades!$J$2:$J$598 )} -> 0.68946648 | H30: 45677 | I30: 46010 | J30: =I30-H30 -> 333 | K30: =IFERROR(INDEX(Tabela3[ID_Responsavel], MATCH(L30,Tabela3[[Responsáveis ]], 0)), "Não encontrado") -> 7 | L30: Edimar Dias | M30: SESI
A31: =IFERROR(INDEX(Tabela2[ID_Area], MATCH(B31,Tabela2[Area], 0)), "Não encontrado") -> 1001 | B31: Meio Ambiente - Operação | C31: Planos Diretores | D31: =ROW(D31) +98 -> 129 | E31: Elaborar o Plano Diretor de PRAD do empreendimento, estabelecendo diretrizes e ações para o gerenciamento de águas superficiais, controle de processos erosivos, aplicação de técnicas de bioengenharia e revegetação de taludes nas áreas da SVPM. | F31: =IF(G31=1,"Concluído", IF(TODAY()>I31,"Atrasado", IF(AND(G31=0,TODAY()<I31),"Não iniciado", "Em Andamento"))) -> Atrasado | G31: {=SUMPRODUCT( (Atividades!$E$2:$E$598=Metas!E31) * (Atividades!$O$2:$O$598=Metas!L31), Atividades!$I$2:$I$598, Atividades!$J$2:$J$598 ) / SUMPRODUCT( (Atividades!$E$2:$E$598=Metas!E31) * (Atividades!$O$2:$O$598=Metas!L31), Atividades!$J$2:$J$598 )} -> 0.93043478 | H31: 45659 | I31: 46022 | J31: =I31-H31 -> 363 | K31: =IFERROR(INDEX(Tabela3[ID_Responsavel], MATCH(L31,Tabela3[[Responsáveis ]], 0)), "Não encontrado") -> 1 | L31: Alan Boni | M31: SVPM | N31: Alinhado com a Gerencia que a meta será concluída no início de 2026 com a realização do workshop e treinamento das equipes operacionais | O31: Não
A32: =IFERROR(INDEX(Tabela2[ID_Area], MATCH(B32,Tabela2[Area], 0)), "Não encontrado") -> 1001 | B32: Meio Ambiente - Operação | C32: PRAD | D32: =ROW(D32) +98 -> 130 | E32: Desenvolvimento de protocolo de monitoramento para conclusão de áreas de PRAD da Serra Verde | F32: =IF(G32=1,"Concluído", IF(TODAY()>I32,"Atrasado", IF(AND(G32=0,TODAY()<I32),"Não iniciado", "Em Andamento"))) -> Concluído | G32: {=SUMPRODUCT( (Atividades!$E$2:$E$598=Metas!E32) * (Atividades!$O$2:$O$598=Metas!L32), Atividades!$I$2:$I$598, Atividades!$J$2:$J$598 ) / SUMPRODUCT( (Atividades!$E$2:$E$598=Metas!E32) * (Atividades!$O$2:$O$598=Metas!L32), Atividades!$J$2:$J$598 )} -> 1 | H32: 45659 | I32: 45960 | J32: =I32-H32 -> 301 | K32: =IFERROR(INDEX(Tabela3[ID_Responsavel], MATCH(L32,Tabela3[[Responsáveis ]], 0)), "Não encontrado") -> 1 | L32: Alan Boni | M32: SVPM | O32: Sim
A33: =IFERROR(INDEX(Tabela2[ID_Area], MATCH(B33,Tabela2[Area], 0)), "Não encontrado") -> 1001 | B33: Meio Ambiente - Operação | C33: Planos Diretores | D33: =ROW(D33) +98 -> 131 | E33: Elaborar o Plano Diretor de Controles Ambientais do empreendimento | F33: =IF(G33=1,"Concluído", IF(TODAY()>I33,"Atrasado", IF(AND(G33=0,TODAY()<I33),"Não iniciado", "Em Andamento"))) -> Atrasado | G33: {=SUMPRODUCT( (Atividades!$E$2:$E$598=Metas!E33) * (Atividades!$O$2:$O$598=Metas!L33), Atividades!$I$2:$I$598, Atividades!$J$2:$J$598 ) / SUMPRODUCT( (Atividades!$E$2:$E$598=Metas!E33) * (Atividades!$O$2:$O$598=Metas!L33), Atividades!$J$2:$J$598 )} -> 0.82913907 | H33: 45659 | I33: 46003 | J33: =I33-H33 -> 344 | K33: =IFERROR(INDEX(Tabela3[ID_Responsavel], MATCH(L33,Tabela3[[Responsáveis ]], 0)), "Não encontrado") -> 1 | L33: Alan Boni | M33: SVPM | N33: Alinhado com a Gerencia que a meta será concluída no início de 2026 com a realização do workshop e treinamento das equipes operacionais | O33: Não
A34: =IFERROR(INDEX(Tabela2[ID_Area], MATCH(B34,Tabela2[Area], 0)), "Não encontrado") -> 1001 | B34: Meio Ambiente - Operação | C34: SGA | D34: =ROW(D34) +98 -> 132 | E34: Desenvolver e Implementar do Indice de Maturidade e regras socioambientais. | F34: =IF(G34=1,"Concluído", IF(TODAY()>I34,"Atrasado", IF(AND(G34=0,TODAY()<I34),"Não iniciado", "Em Andamento"))) -> Atrasado | G34: {=SUMPRODUCT( (Atividades!$E$2:$E$598=Metas!E34) * (Atividades!$O$2:$O$598=Metas!L34), Atividades!$I$2:$I$598, Atividades!$J$2:$J$598 ) / SUMPRODUCT( (Atividades!$E$2:$E$598=Metas!E34) * (Atividades!$O$2:$O$598=Metas!L34), Atividades!$J$2:$J$598 )} -> 0.39322581 | H34: 45674 | I34: 46022 | J34: =I34-H34 -> 348 | K34: =IFERROR(INDEX(Tabela3[ID_Responsavel], MATCH(L34,Tabela3[[Responsáveis ]], 0)), "Não encontrado") -> 1 | L34: Alan Boni | M34: SVPM | N34: Início em 2026. | O34: Não
A35: =IFERROR(INDEX(Tabela2[ID_Area], MATCH(B35,Tabela2[Area], 0)), "Não encontrado") -> 1001 | B35: Meio Ambiente - Operação | C35: P&D | D35: =ROW(D35) +98 -> 133 | E35: Desenvolvimento de experimentos com técnicas de recuperação de áreas degradadas. | F35: =IF(G35=1,"Concluído", IF(TODAY()>I35,"Atrasado", IF(AND(G35=0,TODAY()<I35),"Não iniciado", "Em Andamento"))) -> Atrasado | G35: {=SUMPRODUCT( (Atividades!$E$2:$E$598=Metas!E35) * (Atividades!$O$2:$O$598=Metas!L35), Atividades!$I$2:$I$598, Atividades!$J$2:$J$598 ) / SUMPRODUCT( (Atividades!$E$2:$E$598=Metas!E35) * (Atividades!$O$2:$O$598=Metas!L35), Atividades!$J$2:$J$598 )} -> 0.15137615 | H35: 45660 | I35: 45960 | J35: =I35-H35 -> 300 | K35: =IFERROR(INDEX(Tabela3[ID_Responsavel], MATCH(L35,Tabela3[[Responsáveis ]], 0)), "Não encontrado") -> 13 | L35: Leovigildo | M35: SESI | N35: A meta é dependente da aquisição dos insumos do PRAD e Bioengenharia. Serão entregues à SVPM somente em janeiro de 2026. | O35: Não
A36: =IFERROR(INDEX(Tabela2[ID_Area], MATCH(B36,Tabela2[Area], 0)), "Não encontrado") -> 1002 | B36: Meio Biótico | C36: PRAD | D36: =ROW(D36) +98 -> 134 | E36: Desenvolver trabalho técnico florestal com base na implantação e resultados iniciais do PRAD Piloto. | F36: =IF(G36=1,"Concluído", IF(TODAY()>I36,"Atrasado", IF(AND(G36=0,TODAY()<I36),"Não iniciado", "Em Andamento"))) -> Concluído | G36: {=SUMPRODUCT( (Atividades!$E$2:$E$598=Metas!E36) * (Atividades!$O$2:$O$598=Metas!L36), Atividades!$I$2:$I$598, Atividades!$J$2:$J$598 ) / SUMPRODUCT( (Atividades!$E$2:$E$598=Metas!E36) * (Atividades!$O$2:$O$598=Metas!L36), Atividades!$J$2:$J$598 )} -> 1 | H36: 45660 | I36: 46021 | J36: =I36-H36 -> 361 | K36: =IFERROR(INDEX(Tabela3[ID_Responsavel], MATCH(L36,Tabela3[[Responsáveis ]], 0)), "Não encontrado") -> 13 | L36: Leovigildo | M36: SESI | N36: Exceto a submissão do trabalho em periódico científico, todas as outras etapas foram finalizadas. No entanto, a submissão depende ainda da aprovação da Relações Institucionais e Responsabilidade Social Responsabilidade Social Corporativa. | O36: Sim
A37: =IFERROR(INDEX(Tabela2[ID_Area], MATCH(B37,Tabela2[Area], 0)), "Não encontrado") -> 1001 | B37: Meio Ambiente - Operação | C37: Planos Diretores | D37: =ROW(D37) +98 -> 135 | E37: De acordo com as premissas do Plano diretor de PRAD, firmar parcerias com instituições de pesquisa / pesquisadores autônomos para estudos aprofundados relacionados a estratégias para recuperação do cerrado. | F37: =IF(G37=1,"Concluído", IF(TODAY()>I37,"Atrasado", IF(AND(G37=0,TODAY()<I37),"Não iniciado", "Em Andamento"))) -> Atrasado | G37: {=SUMPRODUCT( (Atividades!$E$2:$E$598=Metas!E37) * (Atividades!$O$2:$O$598=Metas!L37), Atividades!$I$2:$I$598, Atividades!$J$2:$J$598 ) / SUMPRODUCT( (Atividades!$E$2:$E$598=Metas!E37) * (Atividades!$O$2:$O$598=Metas!L37), Atividades!$J$2:$J$598 )} -> 0.74642127 | H37: 45672 | I37: 45961 | J37: =I37-H37 -> 289 | K37: =IFERROR(INDEX(Tabela3[ID_Responsavel], MATCH(L37,Tabela3[[Responsáveis ]], 0)), "Não encontrado") -> 13 | L37: Leovigildo | M37: SESI | N37: Dependente da aquisição dos insumos de PRAD e Bioengenharia, que só serão entregues à SVPM em janeiro de 2026. | O37: Não
A38: =IFERROR(INDEX(Tabela2[ID_Area], MATCH(B38,Tabela2[Area], 0)), "Não encontrado") -> 1002 | B38: Meio Biótico | C38: P&D | D38: =ROW(D38) +98 -> 136 | E38: Apresentar e testar novas soluções para controle de sedimentos do empreendimento. | F38: =IF(G38=1,"Concluído", IF(TODAY()>I38,"Atrasado", IF(AND(G38=0,TODAY()<I38),"Não iniciado", "Em Andamento"))) -> Atrasado | G38: {=SUMPRODUCT( (Atividades!$E$2:$E$598=Metas!E38) * (Atividades!$O$2:$O$598=Metas!L38), Atividades!$I$2:$I$598, Atividades!$J$2:$J$598 ) / SUMPRODUCT( (Atividades!$E$2:$E$598=Metas!E38) * (Atividades!$O$2:$O$598=Metas!L38), Atividades!$J$2:$J$598 )} -> 0.97839506 | H38: 45731 | I38: 46011 | J38: =I38-H38 -> 280 | K38: =IFERROR(INDEX(Tabela3[ID_Responsavel], MATCH(L38,Tabela3[[Responsáveis ]], 0)), "Não encontrado") -> 13 | L38: Leovigildo | M38: SESI | N38: Impantadas duas soluções reaproveitando lonas de filtragem: 01 para a proteção de taludes e controle de plantas daninhas por solarização no PRAD Piloto; 01 como construção de paliçadas para a retenção de sedimentos na Cava Sul. | O38: Não
A39: =IFERROR(INDEX(Tabela2[ID_Area], MATCH(B39,Tabela2[Area], 0)), "Não encontrado") -> 1001 | B39: Meio Ambiente - Operação | C39: Controle Ambiental | D39: =ROW(D39) +98 -> 137 | E39: Implementar o Plano Diretor de Controles Ambientais (PDCA) do empreendimento. | F39: =IF(G39=1,"Concluído", IF(TODAY()>I39,"Atrasado", IF(AND(G39=0,TODAY()<I39),"Não iniciado", "Em Andamento"))) -> Atrasado | G39: {=SUMPRODUCT( (Atividades!$E$2:$E$598=Metas!E39) * (Atividades!$O$2:$O$598=Metas!L39), Atividades!$I$2:$I$598, Atividades!$J$2:$J$598 ) / SUMPRODUCT( (Atividades!$E$2:$E$598=Metas!E39) * (Atividades!$O$2:$O$598=Metas!L39), Atividades!$J$2:$J$598 )} -> 0.64950166 | H39: 45659 | I39: 46022 | J39: =I39-H39 -> 363 | K39: =IFERROR(INDEX(Tabela3[ID_Responsavel], MATCH(L39,Tabela3[[Responsáveis ]], 0)), "Não encontrado") -> 22 | L39: Pedro Duque | M39: SVPM | N39: Alinhado com a Gerencia que a meta será concluída no início de 2026 com a realização do workshop e treinamento das equipes operacionais | O39: Não
A40: =IFERROR(INDEX(Tabela2[ID_Area], MATCH(B40,Tabela2[Area], 0)), "Não encontrado") -> 1001 | B40: Meio Ambiente - Operação | C40: Controle Ambiental | D40: =ROW(D40) +98 -> 138 | E40: Determinar as principais bacias de drenagem natural da ADA SVPM e suas contribuições pluviais, para determinar a origem dos impactos de turbidez das bacias. | F40: =IF(G40=1,"Concluído", IF(TODAY()>I40,"Atrasado", IF(AND(G40=0,TODAY()<I40),"Não iniciado", "Em Andamento"))) -> Concluído | G40: {=SUMPRODUCT( (Atividades!$E$2:$E$598=Metas!E40) * (Atividades!$O$2:$O$598=Metas!L40), Atividades!$I$2:$I$598, Atividades!$J$2:$J$598 ) / SUMPRODUCT( (Atividades!$E$2:$E$598=Metas!E40) * (Atividades!$O$2:$O$598=Metas!L40), Atividades!$J$2:$J$598 )} -> 1 | H40: 45659 | I40: 46022 | J40: =I40-H40 -> 363 | K40: =IFERROR(INDEX(Tabela3[ID_Responsavel], MATCH(L40,Tabela3[[Responsáveis ]], 0)), "Não encontrado") -> 22 | L40: Pedro Duque | M40: SVPM | O40: Sim
...

Sheet Atividades
A1: ID_Area | B1: Área | C1: Tema | D1: ID_Meta | E1: Descrição da Meta | F1: Atividade | G1: Status da Atividade | H1: Data de Conclusão | I1: % Concluído | J1: Peso da tarefa | K1: Data Inicio | L1: Data Fim | M1: Duração | N1: ID_Responsavel | O1: Responsável | P1: Empresa | Q1: Observação de Acompanhamento
A2: =IFERROR(INDEX(Tabela2[ID_Area], MATCH(B2,Tabela2[Area], 0)), "Não encontrado") -> 1000 | B2: Meio Ambiente - Gerencial | C2: Regulatório | D2: =IFERROR(INDEX(Metas!$D$2:$D$104, MATCH(E2,Metas!$E$2:$E$104, 0)), "Não encontrado") -> 125 | E2: Atualizar base de APP (Vereda, Nascente e cursos hídricos) das propriedades. | F2: Diagnóstico de recursos e planejamento de prioridades | G2: =IF(I2=1,"Concluído", IF(TODAY()>L2,"Atrasado", IF(AND(I2=0,TODAY()<K2),"Não iniciado", "Em Andamento"))) -> Concluído | H2: 45660 | I2: 1 | J2: =IFERROR( M2 / SUMIFS($M:$M, $E:$E, $E2, $O:$O, $O2) * 120, 0 ) -> 0.30795552 | K2: 45660 | L2: 45662 | M2: =L2 - K2 + 1 -> 3 | N2: =IFERROR(INDEX(Tabela3[ID_Responsavel], MATCH(O2,Tabela3[[Responsáveis ]], 0)), "Não encontrado") -> 7 | O2: Edimar Dias | P2: SESI | Q2: Organizado banco de dados
A3: =IFERROR(INDEX(Tabela2[ID_Area], MATCH(B3,Tabela2[Area], 0)), "Não encontrado") -> 1000 | B3: Meio Ambiente - Gerencial | C3: Regulatório | D3: =IFERROR(INDEX(Metas!$D$2:$D$104, MATCH(E3,Metas!$E$2:$E$104, 0)), "Não encontrado") -> 125 | E3: Atualizar base de APP (Vereda, Nascente e cursos hídricos) das propriedades. | F3: Elaboração de escopo para contratação | G3: =IF(I3=1,"Concluído", IF(TODAY()>L3,"Atrasado", IF(AND(I3=0,TODAY()<K3),"Não iniciado", "Em Andamento"))) -> Concluído | H3: 45671 | I3: 1 | J3: =IFERROR( M3 / SUMIFS($M:$M, $E:$E, $E3, $O:$O, $O3) * 120, 0 ) -> 1.7450813 | K3: 45664 | L3: 45680 | M3: =L3 - K3 + 1 -> 17 | N3: =IFERROR(INDEX(Tabela3[ID_Responsavel], MATCH(O3,Tabela3[[Responsáveis ]], 0)), "Não encontrado") -> 7 | O3: Edimar Dias | P3: SESI | Q3: Escopo elaborado
A4: =IFERROR(INDEX(Tabela2[ID_Area], MATCH(B4,Tabela2[Area], 0)), "Não encontrado") -> 1000 | B4: Meio Ambiente - Gerencial | C4: Regulatório | D4: =IFERROR(INDEX(Metas!$D$2:$D$104, MATCH(E4,Metas!$E$2:$E$104, 0)), "Não encontrado") -> 125 | E4: Atualizar base de APP (Vereda, Nascente e cursos hídricos) das propriedades. | F4: Contratação de empresa para levantamento de dados em campo | G4: =IF(I4=1,"Concluído", IF(TODAY()>L4,"Atrasado", IF(AND(I4=0,TODAY()<K4),"Não iniciado", "Em Andamento"))) -> Concluído | I4: 1 | J4: =IFERROR( M4 / SUMIFS($M:$M, $E:$E, $E4, $O:$O, $O4) * 120, 0 ) -> 22.378101 | K4: 45703 | L4: 45920 | M4: =L4 - K4 + 1 -> 218 | N4: =IFERROR(INDEX(Tabela3[ID_Responsavel], MATCH(O4,Tabela3[[Responsáveis ]], 0)), "Não encontrado") -> 7 | O4: Edimar Dias | P4: SESI
A5: =IFERROR(INDEX(Tabela2[ID_Area], MATCH(B5,Tabela2[Area], 0)), "Não encontrado") -> 1000 | B5: Meio Ambiente - Gerencial | C5: Regulatório | D5: =IFERROR(INDEX(Metas!$D$2:$D$104, MATCH(E5,Metas!$E$2:$E$104, 0)), "Não encontrado") -> 125 | E5: Atualizar base de APP (Vereda, Nascente e cursos hídricos) das propriedades. | F5: Reunião de kick off com empresa | G5: =IF(I5=1,"Concluído", IF(TODAY()>L5,"Atrasado", IF(AND(I5=0,TODAY()<K5),"Não iniciado", "Em Andamento"))) -> Concluído | I5: 1 | J5: =IFERROR( M5 / SUMIFS($M:$M, $E:$E, $E5, $O:$O, $O5) * 120, 0 ) -> 19.811805 | K5: 45736 | L5: 45928 | M5: =L5 - K5 + 1 -> 193 | N5: =IFERROR(INDEX(Tabela3[ID_Responsavel], MATCH(O5,Tabela3[[Responsáveis ]], 0)), "Não encontrado") -> 7 | O5: Edimar Dias | P5: SESI
A6: =IFERROR(INDEX(Tabela2[ID_Area], MATCH(B6,Tabela2[Area], 0)), "Não encontrado") -> 1000 | B6: Meio Ambiente - Gerencial | C6: Regulatório | D6: =IFERROR(INDEX(Metas!$D$2:$D$104, MATCH(E6,Metas!$E$2:$E$104, 0)), "Não encontrado") -> 125 | E6: Atualizar base de APP (Vereda, Nascente e cursos hídricos) das propriedades. | F6: Mobilização da empresa | G6: =IF(I6=1,"Concluído", IF(TODAY()>L6,"Atrasado", IF(AND(I6=0,TODAY()<K6),"Não iniciado", "Em Andamento"))) -> Concluído | I6: 1 | J6: =IFERROR( M6 / SUMIFS($M:$M, $E:$E, $E6, $O:$O, $O6) * 120, 0 ) -> 19.606501 | K6: 45740 | L6: 45930 | M6: =L6 - K6 + 1 -> 191 | N6: =IFERROR(INDEX(Tabela3[ID_Responsavel], MATCH(O6,Tabela3[[Responsáveis ]], 0)), "Não encontrado") -> 7 | O6: Edimar Dias | P6: SESI
A7: =IFERROR(INDEX(Tabela2[ID_Area], MATCH(B7,Tabela2[Area], 0)), "Não encontrado") -> 1000 | B7: Meio Ambiente - Gerencial | C7: Regulatório | D7: =IFERROR(INDEX(Metas!$D$2:$D$104, MATCH(E7,Metas!$E$2:$E$104, 0)), "Não encontrado") -> 125 | E7: Atualizar base de APP (Vereda, Nascente e cursos hídricos) das propriedades. | F7: Realização do trabalho de campo | G7: =IF(I7=1,"Concluído", IF(TODAY()>L7,"Atrasado", IF(AND(I7=0,TODAY()<K7),"Não iniciado", "Em Andamento"))) -> Concluído | I7: 1 | J7: =IFERROR( M7 / SUMIFS($M:$M, $E:$E, $E7, $O:$O, $O7) * 120, 0 ) -> 16.73225 | K7: 45778 | L7: 45940 | M7: =L7 - K7 + 1 -> 163 | N7: =IFERROR(INDEX(Tabela3[ID_Responsavel], MATCH(O7,Tabela3[[Responsáveis ]], 0)), "Não encontrado") -> 7 | O7: Edimar Dias | P7: SESI
A8: =IFERROR(INDEX(Tabela2[ID_Area], MATCH(B8,Tabela2[Area], 0)), "Não encontrado") -> 1000 | B8: Meio Ambiente - Gerencial | C8: Regulatório | D8: =IFERROR(INDEX(Metas!$D$2:$D$104, MATCH(E8,Metas!$E$2:$E$104, 0)), "Não encontrado") -> 125 | E8: Atualizar base de APP (Vereda, Nascente e cursos hídricos) das propriedades. | F8: Entrega preliminar | G8: =IF(I8=1,"Concluído", IF(TODAY()>L8,"Atrasado", IF(AND(I8=0,TODAY()<K8),"Não iniciado", "Em Andamento"))) -> Concluído | I8: 1 | J8: =IFERROR( M8 / SUMIFS($M:$M, $E:$E, $E8, $O:$O, $O8) * 120, 0 ) -> 13.96065 | K8: 45846 | L8: 45981 | M8: =L8 - K8 + 1 -> 136 | N8: =IFERROR(INDEX(Tabela3[ID_Responsavel], MATCH(O8,Tabela3[[Responsáveis ]], 0)), "Não encontrado") -> 7 | O8: Edimar Dias | P8: SESI
A9: =IFERROR(INDEX(Tabela2[ID_Area], MATCH(B9,Tabela2[Area], 0)), "Não encontrado") -> 1000 | B9: Meio Ambiente - Gerencial | C9: Regulatório | D9: =IFERROR(INDEX(Metas!$D$2:$D$104, MATCH(E9,Metas!$E$2:$E$104, 0)), "Não encontrado") -> 125 | E9: Atualizar base de APP (Vereda, Nascente e cursos hídricos) das propriedades. | F9: Revisão da entrega | G9: =IF(I9=1,"Concluído", IF(TODAY()>L9,"Atrasado", IF(AND(I9=0,TODAY()<K9),"Não iniciado", "Em Andamento"))) -> Concluído | I9: 1 | J9: =IFERROR( M9 / SUMIFS($M:$M, $E:$E, $E9, $O:$O, $O9) * 120, 0 ) -> 12.934132 | K9: 45860 | L9: 45985 | M9: =L9 - K9 + 1 -> 126 | N9: =IFERROR(INDEX(Tabela3[ID_Responsavel], MATCH(O9,Tabela3[[Responsáveis ]], 0)), "Não encontrado") -> 7 | O9: Edimar Dias | P9: SESI
A10: =IFERROR(INDEX(Tabela2[ID_Area], MATCH(B10,Tabela2[Area], 0)), "Não encontrado") -> 1000 | B10: Meio Ambiente - Gerencial | C10: Regulatório | D10: =IFERROR(INDEX(Metas!$D$2:$D$104, MATCH(E10,Metas!$E$2:$E$104, 0)), "Não encontrado") -> 125 | E10: Atualizar base de APP (Vereda, Nascente e cursos hídricos) das propriedades. | F10: Entrega final da base atualizada | G10: =IF(I10=1,"Concluído", IF(TODAY()>L10,"Atrasado", IF(AND(I10=0,TODAY()<K10),"Não iniciado", "Em Andamento"))) -> Concluído | I10: 1 | J10: =IFERROR( M10 / SUMIFS($M:$M, $E:$E, $E10, $O:$O, $O10) * 120, 0 ) -> 12.523524 | K10: 45868 | L10: 45989 | M10: =L10 - K10 + 1 -> 122 | N10: =IFERROR(INDEX(Tabela3[ID_Responsavel], MATCH(O10,Tabela3[[Responsáveis ]], 0)), "Não encontrado") -> 7 | O10: Edimar Dias | P10: SESI
A11: =IFERROR(INDEX(Tabela2[ID_Area], MATCH(B11,Tabela2[Area], 0)), "Não encontrado") -> 1000 | B11: Meio Ambiente - Gerencial | C11: Regulatório | D11: =IFERROR(INDEX(Metas!$D$2:$D$104, MATCH(E11,Metas!$E$2:$E$104, 0)), "Não encontrado") -> 123 | E11: REGULARIZAÇÃO CAR - Atualização das informações e adequação das bases das propriedades inseridas na ADA SVPM conforme prioridade e disponibilidade de recurso. | F11: Diagnóstico das bases das propriedades incluindo atualização das APPs | G11: =IF(I11=1,"Concluído", IF(TODAY()>L11,"Atrasado", IF(AND(I11=0,TODAY()<K11),"Não iniciado", "Em Andamento"))) -> Concluído | I11: 1 | J11: =IFERROR( M11 / SUMIFS($M:$M, $E:$E, $E11, $O:$O, $O11) * 120, 0 ) -> 39.466667 | K11: 45847 | L11: 45994 | M11: =L11 - K11 + 1 -> 148 | N11: =IFERROR(INDEX(Tabela3[ID_Responsavel], MATCH(O11,Tabela3[[Responsáveis ]], 0)), "Não encontrado") -> 7 | O11: Edimar Dias | P11: SESI
A12: =IFERROR(INDEX(Tabela2[ID_Area], MATCH(B12,Tabela2[Area], 0)), "Não encontrado") -> 1000 | B12: Meio Ambiente - Gerencial | C12: Regulatório | D12: =IFERROR(INDEX(Metas!$D$2:$D$104, MATCH(E12,Metas!$E$2:$E$104, 0)), "Não encontrado") -> 123 | E12: REGULARIZAÇÃO CAR - Atualização das informações e adequação das bases das propriedades inseridas na ADA SVPM conforme prioridade e disponibilidade de recurso. | F12: Atualização da base | G12: =IF(I12=1,"Concluído", IF(TODAY()>L12,"Atrasado", IF(AND(I12=0,TODAY()<K12),"Não iniciado", "Em Andamento"))) -> Concluído | I12: 1 | J12: =IFERROR( M12 / SUMIFS($M:$M, $E:$E, $E12, $O:$O, $O12) * 120, 0 ) -> 26.133333 | K12: 45899 | L12: 45996 | M12: =L12 - K12 + 1 -> 98 | N12: =IFERROR(INDEX(Tabela3[ID_Responsavel], MATCH(O12,Tabela3[[Responsáveis ]], 0)), "Não encontrado") -> 7 | O12: Edimar Dias | P12: SESI
A13: =IFERROR(INDEX(Tabela2[ID_Area], MATCH(B13,Tabela2[Area], 0)), "Não encontrado") -> 1000 | B13: Meio Ambiente - Gerencial | C13: Regulatório | D13: =IFERROR(INDEX(Metas!$D$2:$D$104, MATCH(E13,Metas!$E$2:$E$104, 0)), "Não encontrado") -> 123 | E13: REGULARIZAÇÃO CAR - Atualização das informações e adequação das bases das propriedades inseridas na ADA SVPM conforme prioridade e disponibilidade de recurso. | F13: Reunião para apresentação da base atualizada para Gerencia de MA | G13: =IF(I13=1,"Concluído", IF(TODAY()>L13,"Atrasado", IF(AND(I13=0,TODAY()<K13),"Não iniciado", "Em Andamento"))) -> Concluído | I13: 1 | J13: =IFERROR( M13 / SUMIFS($M:$M, $E:$E, $E13, $O:$O, $O13) * 120, 0 ) -> 18.933333 | K13: 45931 | L13: 46001 | M13: =L13 - K13 + 1 -> 71 | N13: =IFERROR(INDEX(Tabela3[ID_Responsavel], MATCH(O13,Tabela3[[Responsáveis ]], 0)), "Não encontrado") -> 7 | O13: Edimar Dias | P13: SESI
A14: =IFERROR(INDEX(Tabela2[ID_Area], MATCH(B14,Tabela2[Area], 0)), "Não encontrado") -> 1000 | B14: Meio Ambiente - Gerencial | C14: Regulatório | D14: =IFERROR(INDEX(Metas!$D$2:$D$104, MATCH(E14,Metas!$E$2:$E$104, 0)), "Não encontrado") -> 123 | E14: REGULARIZAÇÃO CAR - Atualização das informações e adequação das bases das propriedades inseridas na ADA SVPM conforme prioridade e disponibilidade de recurso. | F14: Aprovação do jurídico | G14: =IF(I14=1,"Concluído", IF(TODAY()>L14,"Atrasado", IF(AND(I14=0,TODAY()<K14),"Não iniciado", "Em Andamento"))) -> Concluído | I14: 1 | J14: =IFERROR( M14 / SUMIFS($M:$M, $E:$E, $E14, $O:$O, $O14) * 120, 0 ) -> 16.533333 | K14: 45943 | L14: 46004 | M14: =L14 - K14 + 1 -> 62 | N14: =IFERROR(INDEX(Tabela3[ID_Responsavel], MATCH(O14,Tabela3[[Responsáveis ]], 0)), "Não encontrado") -> 7 | O14: Edimar Dias | P14: SESI
A15: =IFERROR(INDEX(Tabela2[ID_Area], MATCH(B15,Tabela2[Area], 0)), "Não encontrado") -> 1000 | B15: Meio Ambiente - Gerencial | C15: Regulatório | D15: =IFERROR(INDEX(Metas!$D$2:$D$104, MATCH(E15,Metas!$E$2:$E$104, 0)), "Não encontrado") -> 123 | E15: REGULARIZAÇÃO CAR - Atualização das informações e adequação das bases das propriedades inseridas na ADA SVPM conforme prioridade e disponibilidade de recurso. | F15: Atualização do CAR no SISCAR | G15: =IF(I15=1,"Concluído", IF(TODAY()>L15,"Atrasado", IF(AND(I15=0,TODAY()<K15),"Não iniciado", "Em Andamento"))) -> Concluído | I15: 1 | J15: =IFERROR( M15 / SUMIFS($M:$M, $E:$E, $E15, $O:$O, $O15) * 120, 0 ) -> 18.933333 | K15: 45951 | L15: 46021 | M15: =L15 - K15 + 1 -> 71 | N15: =IFERROR(INDEX(Tabela3[ID_Responsavel], MATCH(O15,Tabela3[[Responsáveis ]], 0)), "Não encontrado") -> 7 | O15: Edimar Dias | P15: SESI
... A23: =IFERROR(INDEX(Tabela2[ID_Area], MATCH(B23,Tabela2[Area], 0)), "Não encontrado") -> 1000 | B23: Meio Ambiente - Gerencial | C23: SGA | D23: =IFERROR(INDEX(Metas!$D$2:$D$104, MATCH(E23,Metas!$E$2:$E$104, 0)), "Não encontrado") -> 124 | E23: Desenvolver e Implementar do Indice de Maturidade e regras socioambientais | F23: Startar o IMA para as áreas | G23: =IF(I23=1,"Concluído", IF(TODAY()>L23,"Atrasado", IF(AND(I23=0,TODAY()<K23),"Não iniciado", "Em Andamento"))) -> Concluído | I23: 1 | J23: =IFERROR( M23 / SUMIFS($M:$M, $E:$E, $E23, $O:$O, $O23) * 120, 0 ) -> 21.311806 | K23: 45814 | L23: 45989 | M23: =L23 - K23 + 1 -> 176 | N23: =IFERROR(INDEX(Tabela3[ID_Responsavel], MATCH(O23,Tabela3[[Responsáveis ]], 0)), "Não encontrado") -> 7 | O23: Edimar Dias | P23: SESI
A24: =IFERROR(INDEX(Tabela2[ID_Area], MATCH(B24,Tabela2[Area], 0)), "Não encontrado") -> 1000 | B24: Meio Ambiente - Gerencial | C24: Projeto | D24: =IFERROR(INDEX(Metas!$D$2:$D$104, MATCH(E24,Metas!$E$2:$E$104, 0)), "Não encontrado") -> 126 | E24: Rehabilitation Projects Phase II | F24: Elaborar cronograma de acompanhamento do Rehabilitation projects phase II | G24: =IF(I24=1,"Concluído", IF(TODAY()>L24,"Atrasado", IF(AND(I24=0,TODAY()<K24),"Não iniciado", "Em Andamento"))) -> Concluído | I24: 1 | J24: =IFERROR( M24 / SUMIFS($M:$M, $E:$E, $E24, $O:$O, $O24) * 120, 0 ) -> 35.134228 | K24: 45663 | L24: 46011 | M24: =L24 - K24 + 1 -> 349 | N24: =IFERROR(INDEX(Tabela3[ID_Responsavel], MATCH(O24,Tabela3[[Responsáveis ]], 0)), "Não encontrado") -> 7 | O24: Edimar Dias | P24: SESI | Q24: Foi elaborado e apresentado a gerência de MA o levantamento sobre todos os projetos Rehabilitation projects phase II
A25: =IFERROR(INDEX(Tabela2[ID_Area], MATCH(B25,Tabela2[Area], 0)), "Não encontrado") -> 1000 | B25: Meio Ambiente - Gerencial | C25: Projeto | D25: =IFERROR(INDEX(Metas!$D$2:$D$104, MATCH(E25,Metas!$E$2:$E$104, 0)), "Não encontrado") -> 126 | E25: Rehabilitation Projects Phase II | F25: Realizar reunião com equipe aplicando Ciclo PDCA para avaliação das oportunidades de 2025 frente ao acompanhamento 2024 | G25: =IF(I25=1,"Concluído", IF(TODAY()>L25,"Atrasado", IF(AND(I25=0,TODAY()<K25),"Não iniciado", "Em Andamento"))) -> Concluído | I25: 1 | J25: =IFERROR( M25 / SUMIFS($M:$M, $E:$E, $E25, $O:$O, $O25) * 120, 0 ) -> 31.409396 | K25: 45708 | L25: 46019 | M25: =L25 - K25 + 1 -> 312 | N25: =IFERROR(INDEX(Tabela3[ID_Responsavel], MATCH(O25,Tabela3[[Responsáveis ]], 0)), "Não encontrado") -> 7 | O25: Edimar Dias | P25: SESI
A26: =IFERROR(INDEX(Tabela2[ID_Area], MATCH(B26,Tabela2[Area], 0)), "Não encontrado") -> 1000 | B26: Meio Ambiente - Gerencial | C26: Projeto | D26: =IFERROR(INDEX(Metas!$D$2:$D$104, MATCH(E26,Metas!$E$2:$E$104, 0)), "Não encontrado") -> 126 | E26: Rehabilitation Projects Phase II | F26: Elaborar modelo de acompanhamento do desenvolvimento do trabalho ao longo de 2025, de forma a integrar dados de turbidez, controles, reabilitação, pluviometria e consolida-los em informações para tomadas de decisão | G26: =IF(I26=1,"Concluído", IF(TODAY()>L26,"Atrasado", IF(AND(I26=0,TODAY()<K26),"Não iniciado", "Em Andamento"))) -> Concluído | I26: 1 | J26: =IFERROR( M26 / SUMIFS($M:$M, $E:$E, $E26, $O:$O, $O26) * 120, 0 ) -> 30.503356 | K26: 45717 | L26: 46019 | M26: =L26 - K26 + 1 -> 303 | N26: =IFERROR(INDEX(Tabela3[ID_Responsavel], MATCH(O26,Tabela3[[Responsáveis ]], 0)), "Não encontrado") -> 7 | O26: Edimar Dias | P26: SESI
A27: =IFERROR(INDEX(Tabela2[ID_Area], MATCH(B27,Tabela2[Area], 0)), "Não encontrado") -> 1000 | B27: Meio Ambiente - Gerencial | C27: Projeto | D27: =IFERROR(INDEX(Metas!$D$2:$D$104, MATCH(E27,Metas!$E$2:$E$104, 0)), "Não encontrado") -> 126 | E27: Rehabilitation Projects Phase II | F27: Elaborar mensalmente relatório estratégico com informações dos resultados do trabalho | G27: =IF(I27=1,"Concluído", IF(TODAY()>L27,"Atrasado", IF(AND(I27=0,TODAY()<K27),"Não iniciado", "Em Andamento"))) -> Concluído | I27: 1 | J27: =IFERROR( M27 / SUMIFS($M:$M, $E:$E, $E27, $O:$O, $O27) * 120, 0 ) -> 19.127517 | K27: 45741 | L27: 45930 | M27: =L27 - K27 + 1 -> 190 | N27: =IFERROR(INDEX(Tabela3[ID_Responsavel], MATCH(O27,Tabela3[[Responsáveis ]], 0)), "Não encontrado") -> 7 | O27: Edimar Dias | P27: SESI
A28: =IFERROR(INDEX(Tabela2[ID_Area], MATCH(B28,Tabela2[Area], 0)), "Não encontrado") -> 1000 | B28: Meio Ambiente - Gerencial | C28: Projeto | D28: =IFERROR(INDEX(Metas!$D$2:$D$104, MATCH(E28,Metas!$E$2:$E$104, 0)), "Não encontrado") -> 126 | E28: Rehabilitation Projects Phase II | F28: Apresentar resultados preliminares do trabalho realizado | G28: =IF(I28=1,"Concluído", IF(TODAY()>L28,"Atrasado", IF(AND(I28=0,TODAY()<K28),"Não iniciado", "Em Andamento"))) -> Concluído | I28: 1 | J28: =IFERROR( M28 / SUMIFS($M:$M, $E:$E, $E28, $O:$O, $O28) * 120, 0 ) -> 1.9127517 | K28: 45936 | L28: 45954 | M28: =L28 - K28 + 1 -> 19 | N28: =IFERROR(INDEX(Tabela3[ID_Responsavel], MATCH(O28,Tabela3[[Responsáveis ]], 0)), "Não encontrado") -> 7 | O28: Edimar Dias | P28: SESI
A29: =IFERROR(INDEX(Tabela2[ID_Area], MATCH(B29,Tabela2[Area], 0)), "Não encontrado") -> 1000 | B29: Meio Ambiente - Gerencial | C29: Projeto | D29: =IFERROR(INDEX(Metas!$D$2:$D$104, MATCH(E29,Metas!$E$2:$E$104, 0)), "Não encontrado") -> 126 | E29: Rehabilitation Projects Phase II | F29: Realizar reunião técnica com equipe envolvida nos trabalhos apresentando os resultados e lições aprendidas de 2025 e oportunidades 2026 | G29: =IF(I29=1,"Concluído", IF(TODAY()>L29,"Atrasado", IF(AND(I29=0,TODAY()<K29),"Não iniciado", "Em Andamento"))) -> Concluído | I29: 1 | J29: =IFERROR( M29 / SUMIFS($M:$M, $E:$E, $E29, $O:$O, $O29) * 120, 0 ) -> 1.9127517 | K29: 45992 | L29: 46010 | M29: =L29 - K29 + 1 -> 19 | N29: =IFERROR(INDEX(Tabela3[ID_Responsavel], MATCH(O29,Tabela3[[Responsáveis ]], 0)), "Não encontrado") -> 7 | O29: Edimar Dias | P29: SESI
A30: =IFERROR(INDEX(Tabela2[ID_Area], MATCH(B30,Tabela2[Area], 0)), "Não encontrado") -> 1000 | B30: Meio Ambiente - Gerencial | C30: Projeto | D30: =IFERROR(INDEX(Metas!$D$2:$D$104, MATCH(E30,Metas!$E$2:$E$104, 0)), "Não encontrado") -> 127 | E30: Elaborar Book ambiental dos projetos Flow Sheat | F30: Elaborar descrição dos itens que irão compor o Book Ambiental para acompanhamento e registro do desenvolvimento do Flow Sheat | G30: =IF(I30=1,"Concluído", IF(TODAY()>L30,"Atrasado", IF(AND(I30=0,TODAY()<K30),"Não iniciado", "Em Andamento"))) -> Atrasado | I30: 0.01 | J30: =IFERROR( M30 / SUMIFS($M:$M, $E:$E, $E30, $O:$O, $O30) * 120, 0 ) -> 54.086728 | K30: 45677 | L30: 46019 | M30: =L30 - K30 + 1 -> 343 | N30: =IFERROR(INDEX(Tabela3[ID_Responsavel], MATCH(O30,Tabela3[[Responsáveis ]], 0)), "Não encontrado") -> 7 | O30: Edimar Dias | P30: SESI
A31: =IFERROR(INDEX(Tabela2[ID_Area], MATCH(B31,Tabela2[Area], 0)), "Não encontrado") -> 1000 | B31: Meio Ambiente - Gerencial | C31: Projeto | D31: =IFERROR(INDEX(Metas!$D$2:$D$104, MATCH(E31,Metas!$E$2:$E$104, 0)), "Não encontrado") -> 127 | E31: Elaborar Book ambiental dos projetos Flow Sheat | F31: Elaborar cronograma em conjunto com Gerência e Estratégia para acompanhamento de projeto da parte estratégica e operacional | G31: =IF(I31=1,"Concluído", IF(TODAY()>L31,"Atrasado", IF(AND(I31=0,TODAY()<K31),"Não iniciado", "Em Andamento"))) -> Atrasado | I31: 0 | J31: =IFERROR( M31 / SUMIFS($M:$M, $E:$E, $E31, $O:$O, $O31) * 120, 0 ) -> 50.775296 | K31: 45698 | L31: 46019 | M31: =L31 - K31 + 1 -> 322 | N31: =IFERROR(INDEX(Tabela3[ID_Responsavel], MATCH(O31,Tabela3[[Responsáveis ]], 0)), "Não encontrado") -> 7 | O31: Edimar Dias | P31: SESI
A32: =IFERROR(INDEX(Tabela2[ID_Area], MATCH(B32,Tabela2[Area], 0)), "Não encontrado") -> 1000 | B32: Meio Ambiente - Gerencial | C32: Projeto | D32: =IFERROR(INDEX(Metas!$D$2:$D$104, MATCH(E32,Metas!$E$2:$E$104, 0)), "Não encontrado") -> 127 | E32: Elaborar Book ambiental dos projetos Flow Sheat | F32: Apresentar relatório final consolidando as informações referente ao acompanhamento Flow Sheat | G32: =IF(I32=1,"Concluído", IF(TODAY()>L32,"Atrasado", IF(AND(I32=0,TODAY()<K32),"Não iniciado", "Em Andamento"))) -> Atrasado | I32: 0 | J32: =IFERROR( M32 / SUMIFS($M:$M, $E:$E, $E32, $O:$O, $O32) * 120, 0 ) -> 7.7266754 | K32: 45964 | L32: 46012 | M32: =L32 - K32 + 1 -> 49 | N32: =IFERROR(INDEX(Tabela3[ID_Responsavel], MATCH(O32,Tabela3[[Responsáveis ]], 0)), "Não encontrado") -> 7 | O32: Edimar Dias | P32: SESI
A33: =IFERROR(INDEX(Tabela2[ID_Area], MATCH(B33,Tabela2[Area], 0)), "Não encontrado") -> 1000 | B33: Meio Ambiente - Gerencial | C33: Projeto | D33: =IFERROR(INDEX(Metas!$D$2:$D$104, MATCH(E33,Metas!$E$2:$E$104, 0)), "Não encontrado") -> 127 | E33: Elaborar Book ambiental dos projetos Flow Sheat | F33: Realizar Work Shopp técnico com equipe envolvida no projeto para apresentação e discussões abertas sobre as lições aprendidas | G33: =IF(I33=1,"Concluído", IF(TODAY()>L33,"Atrasado", IF(AND(I33=0,TODAY()<K33),"Não iniciado", "Em Andamento"))) -> Atrasado | I33: 0 | J33: =IFERROR( M33 / SUMIFS($M:$M, $E:$E, $E33, $O:$O, $O33) * 120, 0 ) -> 7.4113009 | K33: 45964 | L33: 46010 | M33: =L33 - K33 + 1 -> 47 | N33: =IFERROR(INDEX(Tabela3[ID_Responsavel], MATCH(O33,Tabela3[[Responsáveis ]], 0)), "Não encontrado") -> 7 | O33: Edimar Dias | P33: SESI
A34: =IFERROR(INDEX(Tabela2[ID_Area], MATCH(B34,Tabela2[Area], 0)), "Não encontrado") -> 1000 | B34: Meio Ambiente - Gerencial | C34: Projeto | D34: =IFERROR(INDEX(Metas!$D$2:$D$104, MATCH(E34,Metas!$E$2:$E$104, 0)), "Não encontrado") -> 128 | E34: Elaborar Book ambiental do Heap Laeth | F34: Elaborar descrição dos itens que irão compor o Book Ambiental para acompanhamento e registro do desenvolvimento do Flow Sheat | G34: =IF(I34=1,"Concluído", IF(TODAY()>L34,"Atrasado", IF(AND(I34=0,TODAY()<K34),"Não iniciado", "Em Andamento"))) -> Concluído | I34: 1 | J34: =IFERROR( M34 / SUMIFS($M:$M, $E:$E, $E34, $O:$O, $O34) * 120, 0 ) -> 56.30643 | K34: 45677 | L34: 46019 | M34: =L34 - K34 + 1 -> 343 | N34: =IFERROR(INDEX(Tabela3[ID_Responsavel], MATCH(O34,Tabela3[[Responsáveis ]], 0)), "Não encontrado") -> 7 | O34: Edimar Dias | P34: SESI
A35: =IFERROR(INDEX(Tabela2[ID_Area], MATCH(B35,Tabela2[Area], 0)), "Não encontrado") -> 1000 | B35: Meio Ambiente - Gerencial | C35: Projeto | D35: =IFERROR(INDEX(Metas!$D$2:$D$104, MATCH(E35,Metas!$E$2:$E$104, 0)), "Não encontrado") -> 128 | E35: Elaborar Book ambiental do Heap Laeth | F35: Elaborar cronograma em conjunto com Gerência e Estratégia para acompanhamento de projeto da parte estratégica e operacional | G35: =IF(I35=1,"Concluído", IF(TODAY()>L35,"Atrasado", IF(AND(I35=0,TODAY()<K35),"Não iniciado", "Em Andamento"))) -> Atrasado | I35: 0.5 | J35: =IFERROR( M35 / SUMIFS($M:$M, $E:$E, $E35, $O:$O, $O35) * 120, 0 ) -> 52.859097 | K35: 45698 | L35: 46019 | M35: =L35 - K35 + 1 -> 322 | N35: =IFERROR(INDEX(Tabela3[ID_Responsavel], MATCH(O35,Tabela3[[Responsáveis ]], 0)), "Não encontrado") -> 7 | O35: Edimar Dias | P35: SESI
A36: =IFERROR(INDEX(Tabela2[ID_Area], MATCH(B36,Tabela2[Area], 0)), "Não encontrado") -> 1000 | B36: Meio Ambiente - Gerencial | C36: Projeto | D36: =IFERROR(INDEX(Metas!$D$2:$D$104, MATCH(E36,Metas!$E$2:$E$104, 0)), "Não encontrado") -> 128 | E36: Elaborar Book ambiental do Heap Laeth | F36: Apresentar relatório final consolidando as informações referente ao acompanhamento Flow Sheat | G36: =IF(I36=1,"Concluído", IF(TODAY()>L36,"Atrasado", IF(AND(I36=0,TODAY()<K36),"Não iniciado", "Em Andamento"))) -> Atrasado | I36: 0 | J36: =IFERROR( M36 / SUMIFS($M:$M, $E:$E, $E36, $O:$O, $O36) * 120, 0 ) -> 3.119015 | K36: 45964 | L36: 45982 | M36: =L36 - K36 + 1 -> 19 | N36: =IFERROR(INDEX(Tabela3[ID_Responsavel], MATCH(O36,Tabela3[[Responsáveis ]], 0)), "Não encontrado") -> 7 | O36: Edimar Dias | P36: SESI
